Workbook

Sheet Résumen OD-PRO-03
B2: Resumen OD-PRO-03
B5: Fecha | C5: N°Remito | D5: Número de Tambo | E5: Tambo | F5: Litros (Ticket) | G5: Litros (Planilla) | H5: Diferencia | I5: Temperatura | J5: Grasa | K5: Proteína
B6: 45672 | C6: 0073-00000002 | D6: 10 | E6: =+VLOOKUP(D6,'Código Tambos'!$B$2:$C$6,2,TRUE) -> Huaca Hue | F6: 8555 | G6: 8555 | H6: =+G6-F6 -> 0 | I6: 4
B7: 45673 | C7: 0073-00000004 | D7: 10 | E7: =+VLOOKUP(D7,'Código Tambos'!$B$2:$C$6,2,TRUE) -> Huaca Hue | F7: 8563 | G7: 8534 | H7: =+G7-F7 -> -29 | I7: 3.9
B8: 45674 | C8: 0073-00000005 | D8: 10 | E8: =+VLOOKUP(D8,'Código Tambos'!$B$2:$C$6,2,TRUE) -> Huaca Hue | F8: 8733 | G8: 8812 | H8: =+G8-F8 -> 79 | I8: 3.9
B9: 45675 | C9: 0073-00000006 | D9: 10 | E9: =+VLOOKUP(D9,'Código Tambos'!$B$2:$C$6,2,TRUE) -> Huaca Hue | F9: 8421 | G9: 14930 | H9: =+G9-SUM(F9:F11) -> 347 | I9: 3.9
B10: 45675 | C10: 0073-00000006 | D10: 11 | E10: =+VLOOKUP(D10,'Código Tambos'!$B$2:$C$6,2,TRUE) -> Don Enrique (Amalina) | F10: 3054 | I10: 3.9
B11: 45675 | C11: 0073-00000006 | D11: 12 | E11: =+VLOOKUP(D11,'Código Tambos'!$B$2:$C$6,2,TRUE) -> Santa Isabel | F11: 3108 | I11: 3.9
B12: 45677 | C12: 0073-00000050 | D12: 13 | E12: =+VLOOKUP(D12,'Código Tambos'!$B$2:$C$6,2,TRUE) -> Estancia Aleluya | F12: 5524 | G12: 22200 | H12: =+G12-SUM(F12:F15) -> 754 | I12: 3.5
B13: 45677 | C13: 0073-00000050 | D13: 12 | E13: =+VLOOKUP(D13,'Código Tambos'!$B$2:$C$6,2,TRUE) -> Santa Isabel | F13: 1317 | I13: 3.9
B14: 45677 | C14: 0073-00000050 | D14: 10 | E14: =+VLOOKUP(D14,'Código Tambos'!$B$2:$C$6,2,TRUE) -> Huaca Hue | F14: 9021 | I14: 3.9
B15: 45677 | C15: 0073-00000050 | D15: 11 | E15: =+VLOOKUP(D15,'Código Tambos'!$B$2:$C$6,2,TRUE) -> Don Enrique (Amalina) | F15: 5584 | I15: 3.9
B16: 45678 | C16: 0073-00000050 | D16: 13 | E16: =+VLOOKUP(D16,'Código Tambos'!$B$2:$C$6,2,TRUE) -> Estancia Aleluya | F16: 6054 | G16: 5886 | H16: =+G16-F16 -> -168 | I16: 3.9
B17: 45679 | C17: 0073-00000049 | D17: 13 | E17: =+VLOOKUP(D17,'Código Tambos'!$B$2:$C$6,2,TRUE) -> Estancia Aleluya | F17: 9407 | G17: 9460 | H17: =+G17-F17 -> 53 | I17: 3.9
B18: 45680 | C18: 0073-00000048 | D18: 11 | E18: =+VLOOKUP(D18,'Código Tambos'!$B$2:$C$6,2,TRUE) -> Don Enrique (Amalina) | F18: 1075 | G18: 17480 | H18: =+G18-SUM(F18:F21) -> -375 | I18: 3.9
B19: 45680 | C19: 0073-00000048 | D19: 10 | E19: =+VLOOKUP(D19,'Código Tambos'!$B$2:$C$6,2,TRUE) -> Huaca Hue | F19: 4577 | I19: 3.9
B20: 45680 | C20: 0073-00000048 | D20: 12 | E20: =+VLOOKUP(D20,'Código Tambos'!$B$2:$C$6,2,TRUE) -> Santa Isabel | F20: 2772 | I20: 3.9
B21: 45680 | C21: 0073-00000048 | D21: 13 | E21: =+VLOOKUP(D21,'Código Tambos'!$B$2:$C$6,2,TRUE) -> Estancia Aleluya | F21: 9431 | I21: 3.9
B22: 45681 | C22: 0073-00000007 | D22: 13 | E22: =+VLOOKUP(D22,'Código Tambos'!$B$2:$C$6,2,TRUE) -> Estancia Aleluya | F22: 9618 | G22: 9966 | H22: =+G22-F22 -> 348 | I22: 3.9
B23: 45683 | C23: 0073-00000008 | D23: 11 | E23: =+VLOOKUP(D23,'Código Tambos'!$B$2:$C$6,2,TRUE) -> Don Enrique (Amalina) | F23: 5135 | G23: 29312 | H23: =+G23-SUM(F23:F25) -> 746 | I23: 3.9
B24: 45683 | C24: 0073-00000008 | D24: 10 | E24: =+VLOOKUP(D24,'Código Tambos'!$B$2:$C$6,2,TRUE) -> Huaca Hue | F24: 13440 | I24: 3.9
B25: 45683 | C25: 0073-00000008 | D25: 13 | E25: =+VLOOKUP(D25,'Código Tambos'!$B$2:$C$6,2,TRUE) -> Estancia Aleluya | F25: 9991 | I25: 9
B26: 45683 | C26: 0073-00000008 | D26: 12 | E26: =+VLOOKUP(D26,'Código Tambos'!$B$2:$C$6,2,TRUE) -> Santa Isabel | F26: 2629 | G26: 2662 | H26: =+G26-F26 -> 33 | I26: 3.9
B27: 45684 | C27: 0073-00000010 | D27: 11 | E27: =+VLOOKUP(D27,'Código Tambos'!$B$2:$C$6,2,TRUE) -> Don Enrique (Amalina) | F27: 5054 | G27: 27124 | H27: =+G27-SUM(F27:F30) -> 170 | I27: 3.9
B28: 45684 | C28: 0073-00000010 | D28: 10 | E28: =+VLOOKUP(D28,'Código Tambos'!$B$2:$C$6,2,TRUE) -> Huaca Hue | F28: 8834 | I28: 3.9
B29: 45684 | C29: 0073-00000010 | D29: 12 | E29: =+VLOOKUP(D29,'Código Tambos'!$B$2:$C$6,2,TRUE) -> Santa Isabel | F29: 2716 | I29: 3.9
B30: 45684 | C30: 0073-00000010 | D30: 13 | E30: =+VLOOKUP(D30,'Código Tambos'!$B$2:$C$6,2,TRUE) -> Estancia Aleluya | F30: 10350 | I30: 3.9
B31: 45685 | C31: 0073-00000011 | D31: 11 | E31: =+VLOOKUP(D31,'Código Tambos'!$B$2:$C$6,2,TRUE) -> Don Enrique (Amalina) | F31: 8560 | G31: 27962 | H31: =+G31-SUM(F31:F34) -> 422 | I31: 1.8
B32: 45685 | C32: 0073-00000011 | D32: 10 | E32: =+VLOOKUP(D32,'Código Tambos'!$B$2:$C$6,2,TRUE) -> Huaca Hue | F32: 8710 | I32: 4
B33: 45685 | C33: 0073-00000011 | D33: 12 | E33: =+VLOOKUP(D33,'Código Tambos'!$B$2:$C$6,2,TRUE) -> Santa Isabel | F33: 2586 | I33: 4
B34: 45685 | C34: 0073-00000011 | D34: 13 | E34: =+VLOOKUP(D34,'Código Tambos'!$B$2:$C$6,2,TRUE) -> Estancia Aleluya | F34: 7684 | I34: 4
B35: 45686 | C35: 0073-00000048 | D35: 11 | E35: =+VLOOKUP(D35,'Código Tambos'!$B$2:$C$6,2,TRUE) -> Don Enrique (Amalina) | F35: 5119 | G35: 29124 | H35: =+G35-SUM(F35:F38) -> 775 | I35: 2
B36: 45686 | C36: 0073-00000048 | D36: 10 | E36: =+VLOOKUP(D36,'Código Tambos'!$B$2:$C$6,2,TRUE) -> Huaca Hue | F36: 8599 | I36: 4
B37: 45686 | C37: 0073-00000048 | D37: 12 | E37: =+VLOOKUP(D37,'Código Tambos'!$B$2:$C$6,2,TRUE) -> Santa Isabel | F37: 2490 | I37: 3.6
B38: 45686 | C38: 0073-00000048 | D38: 13 | E38: =+VLOOKUP(D38,'Código Tambos'!$B$2:$C$6,2,TRUE) -> Estancia Aleluya | F38: 12141 | I38: 5
B39: 45687 | C39: 0073-00000013 | D39: 12 | E39: =+IF(D39>0,VLOOKUP(D39,'Código Tambos'!$B$2:$C$6,2,TRUE),0) -> Santa Isabel | F39: 2586 | G39: 2906 | H39: =+G39-F39 -> 320 | I39: 3.9
B40: 45689 | C40: 0073-00000009 | D40: 11 | E40: =+IF(D40>0,VLOOKUP(D40,'Código Tambos'!$B$2:$C$6,2,TRUE),0) -> Don Enrique (Amalina) | F40: 6142 | G40: 15849 | H40: =+G40-SUM(F40:F41) -> 380 | I40: 3.9
B41: 45689 | C41: 0073-00000009 | D41: 10 | E41: =+IF(D41>0,VLOOKUP(D41,'Código Tambos'!$B$2:$C$6,2,TRUE),0) -> Huaca Hue | F41: 9327 | I41: 4.3
B42: 45690 | C42: 0073-00000014 | D42: 11 | E42: =+IF(D42>0,VLOOKUP(D42,'Código Tambos'!$B$2:$C$6,2,TRUE),0) -> Don Enrique (Amalina) | F42: 8995 | G42: 18316 | H42: =+G42-SUM(F42:F43) -> 625 | I42: 3.5
B43: 45690 | C43: 0073-00000014 | D43: 10 | E43: =+IF(D43>0,VLOOKUP(D43,'Código Tambos'!$B$2:$C$6,2,TRUE),0) -> Huaca Hue | F43: 8696 | I43: 4
...

Sheet Código Tambos
A2: Codigo Viejo | B2: Código | C2: Tambo
A3: 1 | B3: 10 | C3: Huaca Hue
A4: 2 | B4: 11 | C4: Don Enrique (Amalina)
A5: 3 | B5: 12 | C5: Santa Isabel
A6: 4 | B6: 13 | C6: Estancia Aleluya
B7: 16-1 | C7: Larregain Hnos (TLR)
B8: 16-2 | C8: Larregain Hnos (TLR)
B9: 21 | C9: Brivio Eduardo (TBR)
B10: 23 | C10: La Victoria
B11: 17 | C11: Raycle S.A.
B12: 22 | C12: Trueba Roberto
B13: 25 | C13: Viejo Ceibo
